<sdf version='1.6'>
  <model name='simple_car'>
    <link name='base_link'>
      <pose frame=''>0 0 0 0 -0 0</pose>
      <inertial>
        <pose frame=''>0 -0 0.010103 0 -0 0</pose>
        <mass>0.19204</mass>
        <inertia>
          <ixx>8.484e-05</ixx>
          <ixy>1.781e-20</ixy>
          <ixz>-5.8812e-21</ixz>
          <iyy>0.00031457</iyy>
          <iyz>-7.5483e-19</iyz>
          <izz>0.00038657</izz>
        </inertia>
      </inertial>
      <collision name='base_link_collision'>
        <pose frame=''>0 0 0 0 -0 0</pose>
        <geometry>
          <mesh>
            <scale>1 1 1</scale>
            <uri>model://simple_car/meshes/base_link.STL</uri>
          </mesh>
        </geometry>
      </collision>
      <visual name='base_link_visual'>
        <pose frame=''>0 0 0 0 -0 0</pose>
        <geometry>
          <mesh>
            <scale>1 1 1</scale>
            <uri>model://simple_car/meshes/base_link.STL</uri>
          </mesh>
        </geometry>
      </visual>
    </link>
    <link name='left_front_wheel'>
      <pose frame=''>0.055 0.04 0.005 -1.5708 0 0</pose>
      <inertial>
        <pose frame=''>-0 -0 -0.002913 0 -0 0</pose>
        <mass>0.0017122</mass>
        <inertia>
          <ixx>4.6397e-08</ixx>
          <ixy>7.122e-26</ixy>
          <ixz>-5.1078e-24</ixz>
          <iyy>4.6397e-08</iyy>
          <iyz>5.7964e-25</iyz>
          <izz>7.9176e-08</izz>
        </inertia>
      </inertial>
      <collision name='left_front_wheel_collision'>
        <pose frame=''>0 0 0 0 -0 0</pose>
        <geometry>
          <mesh>
            <scale>1 1 1</scale>
            <uri>model://simple_car/meshes/left_front_wheel.STL</uri>
          </mesh>
        </geometry>
      </collision>
      <visual name='left_front_wheel_visual'>
        <pose frame=''>0 0 0 0 -0 0</pose>
        <geometry>
          <mesh>
            <scale>1 1 1</scale>
            <uri>model://simple_car/meshes/left_front_wheel.STL</uri>
          </mesh>
        </geometry>
      </visual>
    </link>
    <joint name='left_front_joint' type='revolute'>
      <child>left_front_wheel</child>
      <parent>base_link</parent>
      <axis>
        <xyz>0 1 -4e-06</xyz>
        <limit>
          <lower>-1e+16</lower>
          <upper>1e+16</upper>
        </limit>
        <dynamics>
          <spring_reference>0</spring_reference>
          <spring_stiffness>0</spring_stiffness>
        </dynamics>
        <use_parent_model_frame>1</use_parent_model_frame>
      </axis>
    </joint>
    <link name='left_rear_wheel'>
      <pose frame=''>-0.055 0.04 0.005 -1.5708 0 0</pose>
      <inertial>
        <pose frame=''>0 0 -0.002913 0 -0 0</pose>
        <mass>0.0017122</mass>
        <inertia>
          <ixx>4.6397e-08</ixx>
          <ixy>-1.4364e-38</ixy>
          <ixz>-1.1502e-24</ixz>
          <iyy>4.6397e-08</iyy>
          <iyz>-4.2867e-25</iyz>
          <izz>7.9176e-08</izz>
        </inertia>
      </inertial>
      <collision name='left_rear_wheel_collision'>
        <pose frame=''>0 0 0 0 -0 0</pose>
        <geometry>
          <mesh>
            <scale>1 1 1</scale>
            <uri>model://simple_car/meshes/left_rear_wheel.STL</uri>
          </mesh>
        </geometry>
      </collision>
      <visual name='left_rear_wheel_visual'>
        <pose frame=''>0 0 0 0 -0 0</pose>
        <geometry>
          <mesh>
            <scale>1 1 1</scale>
            <uri>model://simple_car/meshes/left_rear_wheel.STL</uri>
          </mesh>
        </geometry>
      </visual>
    </link>
    <joint name='left_rear_joint' type='revolute'>
      <child>left_rear_wheel</child>
      <parent>base_link</parent>
      <axis>
        <xyz>0 1 -4e-06</xyz>
        <limit>
          <lower>-1e+16</lower>
          <upper>1e+16</upper>
        </limit>
        <dynamics>
          <spring_reference>0</spring_reference>
          <spring_stiffness>0</spring_stiffness>
        </dynamics>
        <use_parent_model_frame>1</use_parent_model_frame>
      </axis>
    </joint>
    <link name='right_front_wheel'>
      <pose frame=''>0.055 -0.04 0.005 -1.5708 0 0</pose>
      <inertial>
        <pose frame=''>0 0 0.002913 0 -0 0</pose>
        <mass>0.0017122</mass>
        <inertia>
          <ixx>4.6397e-08</ixx>
          <ixy>-1.3109e-38</ixy>
          <ixz>-1.0445e-24</ixz>
          <iyy>4.6397e-08</iyy>
          <iyz>-4.6261e-25</iyz>
          <izz>7.9176e-08</izz>
        </inertia>
      </inertial>
      <collision name='right_front_wheel_collision'>
        <pose frame=''>0 0 0 0 -0 0</pose>
        <geometry>
          <mesh>
            <scale>1 1 1</scale>
            <uri>model://simple_car/meshes/right_front_wheel.STL</uri>
          </mesh>
        </geometry>
      </collision>
      <visual name='right_front_wheel_visual'>
        <pose frame=''>0 0 0 0 -0 0</pose>
        <geometry>
          <mesh>
            <scale>1 1 1</scale>
            <uri>model://simple_car/meshes/right_front_wheel.STL</uri>
          </mesh>
        </geometry>
      </visual>
    </link>
    <joint name='right_front_joint' type='revolute'>
      <child>right_front_wheel</child>
      <parent>base_link</parent>
      <axis>
        <xyz>0 1 -4e-06</xyz>
        <limit>
          <lower>-1e+16</lower>
          <upper>1e+16</upper>
        </limit>
        <dynamics>
          <spring_reference>0</spring_reference>
          <spring_stiffness>0</spring_stiffness>
        </dynamics>
        <use_parent_model_frame>1</use_parent_model_frame>
      </axis>
    </joint>
    <link name='right_rear_wheel'>
      <pose frame=''>-0.055 -0.04 0.005 -1.5708 0 0</pose>
      <inertial>
        <pose frame=''>-0 0 0.002913 0 -0 0</pose>
        <mass>0.0017122</mass>
        <inertia>
          <ixx>4.6397e-08</ixx>
          <ixy>1.4275e-38</ixy>
          <ixz>1.1654e-24</ixz>
          <iyy>4.6397e-08</iyy>
          <iyz>-4.6261e-25</iyz>
          <izz>7.9176e-08</izz>
        </inertia>
      </inertial>
      <collision name='right_rear_wheel_collision'>
        <pose frame=''>0 0 0 0 -0 0</pose>
        <geometry>
          <mesh>
            <scale>1 1 1</scale>
            <uri>model://simple_car/meshes/right_rear_wheel.STL</uri>
          </mesh>
        </geometry>
      </collision>
      <visual name='right_rear_wheel_visual'>
        <pose frame=''>0 0 0 0 -0 0</pose>
        <geometry>
          <mesh>
            <scale>1 1 1</scale>
            <uri>model://simple_car/meshes/right_rear_wheel.STL</uri>
          </mesh>
        </geometry>
      </visual>
    </link>
    <joint name='right_rear_joint' type='revolute'>
      <child>right_rear_wheel</child>
      <parent>base_link</parent>
      <axis>
        <xyz>0 1 -4e-06</xyz>
        <limit>
          <lower>-1e+16</lower>
          <upper>1e+16</upper>
        </limit>
        <dynamics>
          <spring_reference>0</spring_reference>
          <spring_stiffness>0</spring_stiffness>
        </dynamics>
        <use_parent_model_frame>1</use_parent_model_frame>
      </axis>
    </joint>
  </model>
</sdf>
