<?xml version="1.0" encoding="utf-8"?>
<!-- This URDF was automatically created by SolidWorks to URDF Exporter! Originally created by Stephen Brawner (brawner@gmail.com) 
     Commit Version: 1.5.1-0-g916b5db  Build Version: 1.5.7152.31018
     For more information, please see http://wiki.ros.org/sw_urdf_exporter -->
<robot
  name="simple_car">
  <link name="base_footprint">
  </link>

  <joint name="fixed" type="fixed">
    <origin xyz="0 0 0.005" rpy="0 0 0"/>
    <parent link="base_footprint"/>
    <child link="base_link"/>
  </joint>

  <link
    name="base_link">
    <inertial>
      <origin
        xyz="0 -9.7145E-17 0.010103"
        rpy="0 0 0" />
      <mass
        value="0.19204" />
      <inertia
        ixx="8.484E-05"
        ixy="1.781E-20"
        ixz="-5.8812E-21"
        iyy="0.00031457"
        iyz="-7.5483E-19"
        izz="0.00038657" />
    </inertial>
    <visual>
      <origin
        xyz="0 0 0"
        rpy="0 0 0" />
      <geometry>
        <mesh
          filename="package://simple_car/meshes/base_link.STL" />
      </geometry>
      <material
        name="">
        <color
          rgba="0.79216 0.81961 0.93333 1" />
      </material>
    </visual>
    <collision>
      <origin
        xyz="0 0 0"
        rpy="0 0 0" />
      <geometry>
        <mesh
          filename="package://simple_car/meshes/base_link.STL" />
      </geometry>
    </collision>
  </link>
  <link
    name="left_front_wheel">
    <inertial>
      <origin
        xyz="-1.3878E-16 -3.4694E-18 -0.0029128"
        rpy="0 0 0" />
      <mass
        value="0.0017122" />
      <inertia
        ixx="4.6397E-08"
        ixy="7.122E-26"
        ixz="-5.1078E-24"
        iyy="4.6397E-08"
        iyz="5.7964E-25"
        izz="7.9176E-08" />
    </inertial>
    <visual>
      <origin
        xyz="0 0 0"
        rpy="0 0 0" />
      <geometry>
        <mesh
          filename="package://simple_car/meshes/left_front_wheel.STL" />
      </geometry>
      <material
        name="">
        <color
          rgba="0.79216 0.81961 0.93333 1" />
      </material>
    </visual>
    <collision>
      <origin
        xyz="0 0 0"
        rpy="0 0 0" />
      <geometry>
        <mesh
          filename="package://simple_car/meshes/left_front_wheel.STL" />
      </geometry>
    </collision>
  </link>
  <joint
    name="left_front_joint"
    type="continuous">
    <origin
      xyz="0.055 0.04 0.005"
      rpy="-1.5708 0 0" />
    <parent
      link="base_link" />
    <child
      link="left_front_wheel" />
    <axis
      xyz="0 0 1" />
  </joint>
  <link
    name="left_rear_wheel">
    <inertial>
      <origin
        xyz="0 0 -0.0029128"
        rpy="0 0 0" />
      <mass
        value="0.0017122" />
      <inertia
        ixx="4.6397E-08"
        ixy="-1.4364E-38"
        ixz="-1.1502E-24"
        iyy="4.6397E-08"
        iyz="-4.2867E-25"
        izz="7.9176E-08" />
    </inertial>
    <visual>
      <origin
        xyz="0 0 0"
        rpy="0 0 0" />
      <geometry>
        <mesh
          filename="package://simple_car/meshes/left_rear_wheel.STL" />
      </geometry>
      <material
        name="">
        <color
          rgba="0.79216 0.81961 0.93333 1" />
      </material>
    </visual>
    <collision>
      <origin
        xyz="0 0 0"
        rpy="0 0 0" />
      <geometry>
        <mesh
          filename="package://simple_car/meshes/left_rear_wheel.STL" />
      </geometry>
    </collision>
  </link>
  <joint
    name="left_rear_joint"
    type="continuous">
    <origin
      xyz="-0.055 0.04 0.005"
      rpy="-1.5708 0 0" />
    <parent
      link="base_link" />
    <child
      link="left_rear_wheel" />
    <axis
      xyz="0 0 1" />
  </joint>
  <link
    name="right_rear_wheel">
    <inertial>
      <origin
        xyz="-1.3878E-17 0 0.0029128"
        rpy="0 0 0" />
      <mass
        value="0.0017122" />
      <inertia
        ixx="4.6397E-08"
        ixy="1.4275E-38"
        ixz="1.1654E-24"
        iyy="4.6397E-08"
        iyz="-4.6261E-25"
        izz="7.9176E-08" />
    </inertial>
    <visual>
      <origin
        xyz="0 0 0"
        rpy="0 0 0" />
      <geometry>
        <mesh
          filename="package://simple_car/meshes/right_rear_wheel.STL" />
      </geometry>
      <material
        name="">
        <color
          rgba="0.79216 0.81961 0.93333 1" />
      </material>
    </visual>
    <collision>
      <origin
        xyz="0 0 0"
        rpy="0 0 0" />
      <geometry>
        <mesh
          filename="package://simple_car/meshes/right_rear_wheel.STL" />
      </geometry>
    </collision>
  </link>
  <joint
    name="right_rear_joint"
    type="continuous">
    <origin
      xyz="-0.055 -0.04 0.005"
      rpy="-1.5708 0 0" />
    <parent
      link="base_link" />
    <child
      link="right_rear_wheel" />
    <axis
      xyz="0 0 1" />
  </joint>
  <link
    name="right_front_wheel">
    <inertial>
      <origin
        xyz="0 0 0.0029128"
        rpy="0 0 0" />
      <mass
        value="0.0017122" />
      <inertia
        ixx="4.6397E-08"
        ixy="-1.3109E-38"
        ixz="-1.0445E-24"
        iyy="4.6397E-08"
        iyz="-4.6261E-25"
        izz="7.9176E-08" />
    </inertial>
    <visual>
      <origin
        xyz="0 0 0"
        rpy="0 0 0" />
      <geometry>
        <mesh
          filename="package://simple_car/meshes/right_front_wheel.STL" />
      </geometry>
      <material
        name="">
        <color
          rgba="0.79216 0.81961 0.93333 1" />
      </material>
    </visual>
    <collision>
      <origin
        xyz="0 0 0"
        rpy="0 0 0" />
      <geometry>
        <mesh
          filename="package://simple_car/meshes/right_front_wheel.STL" />
      </geometry>
    </collision>
  </link>
  <joint
    name="right_front_joint"
    type="continuous">
    <origin
      xyz="0.055 -0.04 0.005"
      rpy="-1.5708 0 0" />
    <parent
      link="base_link" />
    <child
      link="right_front_wheel" />
    <axis
      xyz="0 0 1" />
  </joint>
</robot>